
<robot name="Hound_description" xmlns:xacro="http://www.ros.org/wiki/xacro">
  <material name="black">
    <color rgba="0.0 0.0 0.0 1.0"/>
  </material>
  <material name="blue">
    <color rgba="0.0 0.0 0.8 1.0"/>
  </material>
  <material name="green">
    <color rgba="0.0 0.8 0.0 1.0"/>
  </material>
  <material name="grey">
    <color rgba="0.2 0.2 0.2 1.0"/>
  </material>
  <material name="silver">
    <color rgba="0.913725490196 0.913725490196 0.847058823529 1.0"/>
  </material>
  <material name="orange">
    <color rgba="1.0 0.423529411765 0.0392156862745 1.0"/>
  </material>
  <material name="brown">
    <color rgba="0.870588235294 0.811764705882 0.764705882353 1.0"/>
  </material>
  <material name="red">
    <color rgba="0.8 0.0 0.0 1.0"/>
  </material>
  <material name="white">
    <color rgba="1.0 1.0 1.0 1.0"/>
  </material>

  <link name="trunk">
    <visual>
      <origin rpy="0 0 0" xyz="0 0 0"/>
      <geometry>
        <mesh filename="base.stl" scale="1 1 1"/>
      </geometry>
      <material name="silver"/>
    </visual>
    <collision>
      <origin rpy="0 0 0" xyz="0 0 0"/>
      <geometry>
        <box size="0.56200000 0.25100000 0.14000000"/>
      </geometry>
    </collision>
    <inertial>
      <origin rpy="0 0 0" xyz="0.00131900 0.00023900 0.00387900"/>
      <mass value="18.47623500"/>
      <inertia ixx="0.21721300" ixy="0.00143000" ixz="0.00207600" iyy="0.80351400" iyz="0.00030900" izz="0.95808400"/>
    </inertial>
  </link>


<!--
  <joint name="lidar_fixed" type="fixed">
    <origin rpy="0 0 0" xyz="0.4215 0 -0.070"/>
    <parent link="trunk"/>
    <child link="lidar"/>
  </joint>
  <link name="lidar">
    <visual>
      <origin rpy="0 0 0" xyz="0 0 0"/>
      <geometry>
        <mesh filename="lidar.stl" scale="1 1 1"/>
      </geometry>
      <material name="silver"/>
    </visual>
    <collision>
      <origin rpy="0 0 0" xyz="0.0671 0 0.042"/>
      <geometry>
        <box size="0.140 0.163 0.233"/>
      </geometry>
    </collision>
    <inertial>
      <origin rpy="0 0 0" xyz="0.05231314 0.00155470 0.03320621"/>
      <mass value="1.715"/>
      <inertia ixx="0.01284248" ixy="-0.00000496" ixz="0.00048574" iyy="0.01182010" iyz="-0.00012288" izz="0.00771190"/>
    </inertial>
  </link>

  <joint name="rear_cam_fixed" type="fixed">
    <origin rpy="0 0 0" xyz="-0.4215 0 -0.070"/>
    <parent link="trunk"/>
    <child link="rear_cam"/>
  </joint>
  <link name="rear_cam">
    <visual>
      <origin rpy="0 0 0" xyz="0 0 0"/>
      <geometry>
        <mesh filename="rear_cam.stl" scale="1 1 1"/>
      </geometry>
      <material name="silver"/>
    </visual>
    <collision>
      <origin rpy="0 0 0" xyz="0.0745 0 -0.020"/>
      <geometry>
        <box size="0.150 0.080 0.040"/>
      </geometry>
    </collision>
    <inertial>
      <origin rpy="0 0 0" xyz="0.07235258 -0.00001318 -0.01430797"/>
      <mass value="0.176"/>
      <inertia ixx="0.00008264" ixy="0.00000000" ixz="-0.00000147" iyy="0.00031979" iyz="0.00000000" izz="0.00038072"/>
    </inertial>
  </link>
-->

  <joint name="RR_roll_joint" type="revolute">
    <origin rpy="0 0 0" xyz="-0.35147000 -0.10000000 0.00000000"/>
    <parent link="trunk"/>
    <child link="RR_shoulder"/>
    <axis xyz="1 0 0"/>
    <dynamics rotor_inertia="0.01405600" damping="0" friction="0"/>
    <limit effort="200.00000000" lower="-0.78539816" upper="0.78539816" velocity="21.29000000"/>
  </joint>
  <link name="RR_shoulder">
    <visual>
      <origin rpy="0 3.141592 0" xyz="0 0 0"/>
      <geometry>
        <mesh filename="shoulder.stl" scale="1 1 1"/>
      </geometry>
      <material name="grey"/>
    </visual>
    <collision>
      <origin rpy="1.57079632679 0 0" xyz="0 -0.00500000 0"/>
      <geometry>
        <cylinder length="0.13300000" radius="0.06100000"/>
      </geometry>
    </collision>
    <inertial>
      <origin rpy="0 0 0" xyz="0.00304326 -0.00050825 0.00001789"/>
      <mass value="3.86933709"/>
      <inertia ixx="0.00858804" ixy="-0.00015474" ixz="-0.00000061" iyy="0.00737145" iyz="-0.00000042" izz="0.00928864"/>
    </inertial>
  </link>
  <joint name="RR_hip_joint" type="revolute">
    <origin rpy="0 0 0" xyz="0 -0.11350000 0"/>
    <parent link="RR_shoulder"/>
    <child link="RR_thigh"/>
    <axis xyz="0 1 0"/>
    <dynamics rotor_inertia="0.01405600" damping="0" friction="0"/>
    <limit effort="200.00000000" lower="-6.28318531" upper="6.28318531" velocity="21.29000000"/>
  </joint>
  <link name="RR_thigh">
    <visual>
      <origin rpy="0 0 0" xyz="0 0 0"/>
      <geometry>
        <mesh filename="thigh.stl" scale="1 1 1"/>
      </geometry>
      <material name="grey"/>
    </visual>
    <collision>
      <origin rpy="0 0 0" xyz="0 0 -0.16395000"/>
      <geometry>
        <box size="0.08500000 0.07000000 0.35000000"/>
      </geometry>
    </collision>
    <inertial>
      <origin rpy="0 0 0" xyz="0.00000000 0.01475079 -0.11906126"/>
      <mass value="1.38775820"/>
      <inertia ixx="0.02401331" ixy="0.00000000" ixz="0.00000000" iyy="0.02340658" iyz="0.00229407" izz="0.00240062"/>
    </inertial>
  </link>

  <joint name="RR_knee_joint" type="revolute">
    <origin rpy="0 0 0" xyz="0 0 -0.32790000"/>
    <parent link="RR_thigh"/>
    <child link="RR_calf"/>
    <axis xyz="0 1 0"/>
    <dynamics rotor_inertia="0.05624622" damping="0" friction="0"/>
    <limit effort="400.00000000" lower="-2.79252680" upper="2.79252680" velocity="10.00000000"/>
  </joint>
  <link name="RR_calf">
    <visual>
      <origin rpy="0 0 0" xyz="0 0 0"/>
      <geometry>
        <mesh filename="calf.stl" scale="1 1 1"/>
      </geometry>
      <material name="silver"/>
    </visual>
    <collision>
      <origin rpy="0 0 0" xyz="0 0 -0.20000000"/>
      <geometry>
        <cylinder length="0.26500000" radius="0.02500000"/>
      </geometry>
    </collision>
    <inertial>
      <origin rpy="0 0 0" xyz="-0.00443245 0.00000000 -0.14757071"/>
      <mass value="0.82086930"/>
      <inertia ixx="0.01850881" ixy="0.00000000" ixz="0.00000000" iyy="0.01866790" iyz="0.00000000" izz="0.00061888"/>
    </inertial>
  </link>
  <joint name="RR_foot_fixed" type="fixed">
    <origin rpy="0 0 0" xyz="0 0 -0.34920000"/>
    <parent link="RR_calf"/>
    <child link="RR_foot"/>
  </joint>
  <link name="RR_foot">
<!--
    <visual>
      <origin rpy="0 0 0" xyz="0 0 0"/>
      <geometry>
        <sphere radius="0.06300000"/>
      </geometry>
    </visual>
-->
    <collision>
      <origin rpy="0 0 0" xyz="0 0 0"/>
      <geometry>
        <sphere radius="0.06300000"/>
      </geometry>
    </collision>
    <inertial>
      <origin rpy="0 0 0" xyz="0.0 0.0 0.0"/>
      <mass value="0.010"/>
      <inertia ixx="0.000001" ixy="0.0" ixz="0.0" iyy="0.000001" iyz="0.0" izz="0.000001"/>
    </inertial>
  </link>

	
  <joint name="RL_roll_joint" type="revolute">
    <origin rpy="0 0 0" xyz="-0.35147000 0.10000000 0.00000000"/>
    <parent link="trunk"/>
    <child link="RL_shoulder"/>
    <axis xyz="1 0 0"/>
    <dynamics rotor_inertia="0.01405600" damping="0" friction="0"/>
    <limit effort="200.00000000" lower="-0.78539816" upper="0.78539816" velocity="21.29000000"/>
  </joint>
  <link name="RL_shoulder">
    <visual>
      <origin rpy="0 0 3.141592" xyz="0 0 0"/>
      <geometry>
        <mesh filename="shoulder.stl" scale="1 1 1"/>
      </geometry>
      <material name="grey"/>
    </visual>
    <collision>
      <origin rpy="1.57079632679 0 0" xyz="0 0.00500000 0"/>
      <geometry>
        <cylinder length="0.13300000" radius="0.06100000"/>
      </geometry>
    </collision>
    <inertial>
      <origin rpy="0 0 0" xyz="0.00304326 0.00050825 -0.00001789"/>
      <mass value="3.86933709"/>
      <inertia ixx="0.00858804" ixy="0.00015474" ixz="0.00000061" iyy="0.00737145" iyz="-0.00000042" izz="0.00928864"/>
    </inertial>
  </link>
  <joint name="RL_hip_joint" type="revolute">
    <origin rpy="0 0 0" xyz="0 0.11350000 0"/>
    <parent link="RL_shoulder"/>
    <child link="RL_thigh"/>
    <axis xyz="0 1 0"/>
    <dynamics rotor_inertia="0.01405600" damping="0" friction="0"/>
    <limit effort="200.00000000" lower="-6.28318531" upper="6.28318531" velocity="21.29000000"/>
  </joint>
  <link name="RL_thigh">
    <visual>
      <origin rpy="0 0 3.141592" xyz="0 0 0"/>
      <geometry>
        <mesh filename="thigh.stl" scale="1 1 1"/>
      </geometry>
      <material name="grey"/>
    </visual>
    <collision>
      <origin rpy="0 0 0" xyz="0 0 -0.16395000"/>
      <geometry>
        <box size="0.08500000 0.07000000 0.35000000"/>
      </geometry>
    </collision>
    <inertial>
      <origin rpy="0 0 0" xyz="-0.00000000 -0.01475079 -0.11906126"/>
      <mass value="1.38775820"/>
      <inertia ixx="0.02401331" ixy="0.00000000" ixz="-0.00000000" iyy="0.02340658" iyz="-0.00229407" izz="0.00240062"/>
    </inertial>
  </link>
  <joint name="RL_knee_joint" type="revolute">
    <origin rpy="0 0 0" xyz="0 0 -0.32790000"/>
    <parent link="RL_thigh"/>
    <child link="RL_calf"/>
    <axis xyz="0 1 0"/>
    <dynamics rotor_inertia="0.05624622" damping="0" friction="0"/>
    <limit effort="400.00000000" lower="-2.79252680" upper="2.79252680" velocity="10.00000000"/>
  </joint>
  <link name="RL_calf">
    <visual>
      <origin rpy="0 0 0" xyz="0 0 0"/>
      <geometry>
        <mesh filename="calf.stl" scale="1 1 1"/>
      </geometry>
      <material name="silver"/>
    </visual>
    <collision>
      <origin rpy="0 0 0" xyz="0 0 -0.20000000"/>
      <geometry>
        <cylinder length="0.26500000" radius="0.02500000"/>
      </geometry>
    </collision>
    <inertial>
      <origin rpy="0 0 0" xyz="-0.00443245 -0.00000000 -0.14757071"/>
      <mass value="0.82086930"/>
      <inertia ixx="0.01850881" ixy="-0.00000000" ixz="0.00000000" iyy="0.01866790" iyz="-0.00000000" izz="0.00061888"/>
    </inertial>
  </link>
  <joint name="RL_foot_fixed" type="fixed">
    <origin rpy="0 0 0" xyz="0 0 -0.34920000"/>
    <parent link="RL_calf"/>
    <child link="RL_foot"/>
  </joint>
  <link name="RL_foot">
<!--
    <visual>
      <origin rpy="0 0 0" xyz="0 0 0"/>
      <geometry>
        <sphere radius="0.06300000"/>
      </geometry>
    </visual>
-->
    <collision>
      <origin rpy="0 0 0" xyz="0 0 0"/>
      <geometry>
        <sphere radius="0.06300000"/>
      </geometry>
    </collision>
    <inertial>
      <origin rpy="0 0 0" xyz="0.0 0.0 0.0"/>
      <mass value="0.010"/>
      <inertia ixx="0.000001" ixy="0.0" ixz="0.0" iyy="0.000001" iyz="0.0" izz="0.000001"/>
    </inertial>
  </link>


  <joint name="FR_roll_joint" type="revolute">
    <origin rpy="0 0 0" xyz="0.35147000 -0.10000000 0.00000000"/>
    <parent link="trunk"/>
    <child link="FR_shoulder"/>
    <axis xyz="1 0 0"/>
    <dynamics rotor_inertia="0.01405600" damping="0" friction="0"/>
    <limit effort="200.00000000" lower="-0.78539816" upper="0.78539816" velocity="21.29000000"/>
  </joint>
  <link name="FR_shoulder">
    <visual>
      <origin rpy="0 0 0" xyz="0 0 0"/>
      <geometry>
        <mesh filename="shoulder.stl" scale="1 1 1"/>
      </geometry>
      <material name="grey"/>
    </visual>
    <collision>
      <origin rpy="1.57079632679 0 0" xyz="0 -0.00500000 0"/>
      <geometry>
        <cylinder length="0.13300000" radius="0.06100000"/>
      </geometry>
    </collision>
    <inertial>
      <origin rpy="0 0 0" xyz="-0.00304326 -0.00050825 -0.00001789"/>
      <mass value="3.86933709"/>
      <inertia ixx="0.00858804" ixy="0.00015474" ixz="-0.00000061" iyy="0.00737145" iyz="0.00000042" izz="0.00928864"/>
    </inertial>
  </link>
  <joint name="FR_hip_joint" type="revolute">
    <origin rpy="0 0 0" xyz="0 -0.11350000 0"/>
    <parent link="FR_shoulder"/>
    <child link="FR_thigh"/>
    <axis xyz="0 1 0"/>
    <dynamics rotor_inertia="0.01405600" damping="0" friction="0"/>
    <limit effort="200.00000000" lower="-6.28318531" upper="6.28318531" velocity="21.29000000"/>
  </joint>
  <link name="FR_thigh">
    <visual>
      <origin rpy="0 0 0" xyz="0 0 0"/>
      <geometry>
        <mesh filename="thigh.stl" scale="1 1 1"/>
      </geometry>
      <material name="grey"/>
    </visual>
    <collision>
      <origin rpy="0 0 0" xyz="0 0 -0.16395000"/>
      <geometry>
        <box size="0.08500000 0.07000000 0.35000000"/>
      </geometry>
    </collision>
    <inertial>
      <origin rpy="0 0 0" xyz="0.00000000 0.01475079 -0.11906126"/>
      <mass value="1.38775820"/>
      <inertia ixx="0.02401331" ixy="0.00000000" ixz="0.00000000" iyy="0.02340658" iyz="0.00229407" izz="0.00240062"/>
    </inertial>
  </link>
  <joint name="FR_knee_joint" type="revolute">
    <origin rpy="0 0 0" xyz="0 0 -0.32790000"/>
    <parent link="FR_thigh"/>
    <child link="FR_calf"/>
    <axis xyz="0 1 0"/>
    <dynamics rotor_inertia="0.05624622" damping="0" friction="0"/>
    <limit effort="400.00000000" lower="-2.79252680" upper="2.79252680" velocity="10.00000000"/>
  </joint>
  <link name="FR_calf">
    <visual>
      <origin rpy="0 0 0" xyz="0 0 0"/>
      <geometry>
        <mesh filename="calf.stl" scale="1 1 1"/>
      </geometry>
      <material name="silver"/>
    </visual>
    <collision>
      <origin rpy="0 0 0" xyz="0 0 -0.20000000"/>
      <geometry>
        <cylinder length="0.26500000" radius="0.02500000"/>
      </geometry>
    </collision>
    <inertial>
      <origin rpy="0 0 0" xyz="-0.00443245 0.00000000 -0.14757071"/>
      <mass value="0.82086930"/>
      <inertia ixx="0.01850881" ixy="0.00000000" ixz="0.00000000" iyy="0.01866790" iyz="0.00000000" izz="0.00061888"/>
    </inertial>
  </link>
  <joint name="FR_foot_fixed" type="fixed">
    <origin rpy="0 0 0" xyz="0 0 -0.34920000"/>
    <parent link="FR_calf"/>
    <child link="FR_foot"/>
  </joint>
  <link name="FR_foot">
<!--
    <visual>
      <origin rpy="0 0 0" xyz="0 0 0"/>
      <geometry>
        <sphere radius="0.06300000"/>
      </geometry>
    </visual>
-->
    <collision>
      <origin rpy="0 0 0" xyz="0 0 0"/>
      <geometry>
        <sphere radius="0.06300000"/>
      </geometry>
    </collision>
    <inertial>
      <origin rpy="0 0 0" xyz="0.0 0.0 0.0"/>
      <mass value="0.010"/>
      <inertia ixx="0.000001" ixy="0.0" ixz="0.0" iyy="0.000001" iyz="0.0" izz="0.000001"/>
    </inertial>
  </link>


  <joint name="FL_roll_joint" type="revolute">
    <origin rpy="0 0 0" xyz="0.35147000 0.10000000 0.00000000"/>
    <parent link="trunk"/>
    <child link="FL_shoulder"/>
    <axis xyz="1 0 0"/>
    <dynamics rotor_inertia="0.01405600" damping="0" friction="0"/>
    <limit effort="200.00000000" lower="-0.78539816" upper="0.78539816" velocity="21.29000000"/>
  </joint>
  <link name="FL_shoulder">
    <visual>
      <origin rpy="3.141592 0 0" xyz="0 0 0"/>
      <geometry>
        <mesh filename="shoulder.stl" scale="1 1 1"/>
      </geometry>
      <material name="grey"/>
    </visual>
    <collision>
      <origin rpy="1.57079632679 0 0" xyz="0 0.00500000 0"/>
      <geometry>
        <cylinder length="0.13300000" radius="0.06100000"/>
      </geometry>
    </collision>
    <inertial>
      <origin rpy="0 0 0" xyz="-0.00304326 0.00050825 0.00001789"/>
      <mass value="3.86933709"/>
      <inertia ixx="0.00858804" ixy="-0.00015474" ixz="0.00000061" iyy="0.00737145" iyz="0.00000042" izz="0.00928864"/>
    </inertial>
  </link>
  <joint name="FL_hip_joint" type="revolute">
    <origin rpy="0 0 0" xyz="0 0.11350000 0"/>
    <parent link="FL_shoulder"/>
    <child link="FL_thigh"/>
    <axis xyz="0 1 0"/>
    <dynamics rotor_inertia="0.01405600" damping="0" friction="0"/>
    <limit effort="200.00000000" lower="-6.28318531" upper="6.28318531" velocity="21.29000000"/>
  </joint>
  <link name="FL_thigh">
    <visual>
      <origin rpy="0 0 3.141592" xyz="0 0 0"/>
      <geometry>
        <mesh filename="thigh.stl" scale="1 1 1"/>
      </geometry>
      <material name="grey"/>
    </visual>
    <collision>
      <origin rpy="0 0 0" xyz="0 0 -0.16395000"/>
      <geometry>
        <box size="0.08500000 0.07000000 0.35000000"/>
      </geometry>
    </collision>
    <inertial>
      <origin rpy="0 0 0" xyz="-0.00000000 -0.01475079 -0.11906126"/>
      <mass value="1.38775820"/>
      <inertia ixx="0.02401331" ixy="0.00000000" ixz="-0.00000000" iyy="0.02340658" iyz="-0.00229407" izz="0.00240062"/>
    </inertial>
  </link>
  <joint name="FL_knee_joint" type="revolute">
    <origin rpy="0 0 0" xyz="0 0 -0.32790000"/>
    <parent link="FL_thigh"/>
    <child link="FL_calf"/>
    <axis xyz="0 1 0"/>
    <dynamics rotor_inertia="0.05624622" damping="0" friction="0"/>
    <limit effort="400.00000000" lower="-2.79252680" upper="2.79252680" velocity="10.00000000"/>
  </joint>
  <link name="FL_calf">
    <visual>
      <origin rpy="0 0 0" xyz="0 0 0"/>
      <geometry>
        <mesh filename="calf.stl" scale="1 1 1"/>
      </geometry>
      <material name="silver"/>
    </visual>
    <collision>
      <origin rpy="0 0 0" xyz="0 0 -0.20000000"/>
      <geometry>
        <cylinder length="0.26500000" radius="0.02500000"/>
      </geometry>
    </collision>
    <inertial>
      <origin rpy="0 0 0" xyz="-0.00443245 -0.00000000 -0.14757071"/>
      <mass value="0.82086930"/>
      <inertia ixx="0.01850881" ixy="-0.00000000" ixz="0.00000000" iyy="0.01866790" iyz="-0.00000000" izz="0.00061888"/>
    </inertial>
  </link>
  <joint name="FL_foot_fixed" type="fixed">
    <origin rpy="0 0 0" xyz="0 0 -0.34920000"/>
    <parent link="FL_calf"/>
    <child link="FL_foot"/>
  </joint>
  <link name="FL_foot">
<!--
    <visual>
      <origin rpy="0 0 0" xyz="0 0 0"/>
      <geometry>
        <sphere radius="0.06300000"/>
      </geometry>
    </visual>
-->
    <collision>
      <origin rpy="0 0 0" xyz="0 0 0"/>
      <geometry>
        <sphere radius="0.06300000"/>
      </geometry>
    </collision>
    <inertial>
      <origin rpy="0 0 0" xyz="0.0 0.0 0.0"/>
      <mass value="0.010"/>
      <inertia ixx="0.000001" ixy="0.0" ixz="0.0" iyy="0.000001" iyz="0.0" izz="0.000001"/>
    </inertial>
  </link>


</robot>

